[18-Sep-24 13:55:02 - INFO] - bot - Bot Running..!

Created by 
https://t.me/CodeXBotz
[18-Sep-24 13:55:02 - INFO] - bot -  

       
░█████╗░░█████╗░██████╗░███████╗██╗░░██╗██████╗░░█████╗░████████╗███████╗
██╔══██╗██╔══██╗██╔══██╗██╔════╝╚██╗██╔╝██╔══██╗██╔══██╗╚══██╔══╝╚════██║
██║░░╚═╝██║░░██║██║░░██║█████╗░░░╚███╔╝░██████╦╝██║░░██║░░░██║░░░░░███╔═╝
██║░░██╗██║░░██║██║░░██║██╔══╝░░░██╔██╗░██╔══██╗██║░░██║░░░██║░░░██╔══╝░░
╚█████╔╝╚█████╔╝██████╔╝███████╗██╔╝╚██╗██████╦╝╚█████╔╝░░░██║░░░███████╗
░╚════╝░░╚════╝░╚═════╝░╚══════╝╚═╝░░╚═╝╚═════╝░░╚════╝░░░░╚═╝░░░╚══════╝
                                          
[18-Sep-24 14:06:37 - INFO] - root - Stop signal received (SIGINT). Exiting...
[18-Sep-24 14:06:38 - INFO] - root - Stop signal received (SIGINT). Exiting...
[18-Sep-24 14:06:38 - INFO] - root - Stop signal received (SIGINT). Exiting...
[18-Sep-24 14:06:41 - INFO] - bot - Bot stopped.
[18-Sep-24 14:07:08 - WARNING] - bot - Telegram says: [400 CHANNEL_INVALID] - The channel parameter is invalid (caused by "channels.GetChannels")
[18-Sep-24 14:07:08 - WARNING] - bot - Bot can't Export Invite link from Force Sub Channel!
[18-Sep-24 14:07:08 - WARNING] - bot - Please Double check the FORCE_SUB_CHANNEL value and Make sure Bot is Admin in channel with Invite Users via Link Permission, Current Force Sub Channel Value: -1002299620238
[18-Sep-24 14:07:08 - INFO] - bot - 
Bot Stopped. Join https://t.me/CodeXBotzSupport for support
[18-Sep-24 14:08:11 - INFO] - bot - Bot Running..!

Created by 
https://t.me/CodeXBotz
[18-Sep-24 14:08:11 - INFO] - bot -  

       
░█████╗░░█████╗░██████╗░███████╗██╗░░██╗██████╗░░█████╗░████████╗███████╗
██╔══██╗██╔══██╗██╔══██╗██╔════╝╚██╗██╔╝██╔══██╗██╔══██╗╚══██╔══╝╚════██║
██║░░╚═╝██║░░██║██║░░██║█████╗░░░╚███╔╝░██████╦╝██║░░██║░░░██║░░░░░███╔═╝
██║░░██╗██║░░██║██║░░██║██╔══╝░░░██╔██╗░██╔══██╗██║░░██║░░░██║░░░██╔══╝░░
╚█████╔╝╚█████╔╝██████╔╝███████╗██╔╝╚██╗██████╦╝╚█████╔╝░░░██║░░░███████╗
░╚════╝░░╚════╝░╚═════╝░╚══════╝╚═╝░░╚═╝╚═════╝░░╚════╝░░░░╚═╝░░░╚══════╝
                                          
[18-Sep-24 14:12:53 - INFO] - root - Stop signal received (SIGINT). Exiting...
[18-Sep-24 14:12:53 - INFO] - root - Stop signal received (SIGINT). Exiting...
[18-Sep-24 14:12:53 - INFO] - root - Stop signal received (SIGINT). Exiting...
[18-Sep-24 14:12:54 - INFO] - bot - Bot stopped.
[18-Sep-24 14:13:02 - INFO] - bot - Bot Running..!

Created by 
https://t.me/CodeXBotz
[18-Sep-24 14:13:02 - INFO] - bot -  

       
░█████╗░░█████╗░██████╗░███████╗██╗░░██╗██████╗░░█████╗░████████╗███████╗
██╔══██╗██╔══██╗██╔══██╗██╔════╝╚██╗██╔╝██╔══██╗██╔══██╗╚══██╔══╝╚════██║
██║░░╚═╝██║░░██║██║░░██║█████╗░░░╚███╔╝░██████╦╝██║░░██║░░░██║░░░░░███╔═╝
██║░░██╗██║░░██║██║░░██║██╔══╝░░░██╔██╗░██╔══██╗██║░░██║░░░██║░░░██╔══╝░░
╚█████╔╝╚█████╔╝██████╔╝███████╗██╔╝╚██╗██████╦╝╚█████╔╝░░░██║░░░███████╗
░╚════╝░░╚════╝░╚═════╝░╚══════╝╚═╝░░╚═╝╚═════╝░░╚════╝░░░░╚═╝░░░╚══════╝
                                          
[18-Sep-24 14:13:36 - INFO] - root - Stop signal received (SIGINT). Exiting...
[18-Sep-24 14:13:36 - INFO] - bot - Bot stopped.
[18-Sep-24 14:19:16 - WARNING] - bot - Telegram says: [403 CHAT_ADMIN_REQUIRED] - The method requires chat admin privileges (caused by "messages.ExportChatInvite")
[18-Sep-24 14:19:16 - WARNING] - bot - Bot can't Export Invite link from Force Sub Channel!
[18-Sep-24 14:19:16 - WARNING] - bot - Please Double check the FORCE_SUB_CHANNEL value and Make sure Bot is Admin in channel with Invite Users via Link Permission, Current Force Sub Channel Value: -4577356879
[18-Sep-24 14:19:16 - INFO] - bot - 
Bot Stopped. Join https://t.me/CodeXBotzSupport for support
[18-Sep-24 14:19:37 - WARNING] - bot - Telegram says: [403 CHAT_ADMIN_REQUIRED] - The method requires chat admin privileges (caused by "messages.ExportChatInvite")
[18-Sep-24 14:19:37 - WARNING] - bot - Bot can't Export Invite link from Force Sub Channel!
[18-Sep-24 14:19:37 - WARNING] - bot - Please Double check the FORCE_SUB_CHANNEL value and Make sure Bot is Admin in channel with Invite Users via Link Permission, Current Force Sub Channel Value: -4577356879
[18-Sep-24 14:19:37 - INFO] - bot - 
Bot Stopped. Join https://t.me/CodeXBotzSupport for support
[18-Sep-24 14:19:59 - INFO] - bot - Bot Running..!

Created by 
https://t.me/CodeXBotz
[18-Sep-24 14:19:59 - INFO] - bot -  

       
░█████╗░░█████╗░██████╗░███████╗██╗░░██╗██████╗░░█████╗░████████╗███████╗
██╔══██╗██╔══██╗██╔══██╗██╔════╝╚██╗██╔╝██╔══██╗██╔══██╗╚══██╔══╝╚════██║
██║░░╚═╝██║░░██║██║░░██║█████╗░░░╚███╔╝░██████╦╝██║░░██║░░░██║░░░░░███╔═╝
██║░░██╗██║░░██║██║░░██║██╔══╝░░░██╔██╗░██╔══██╗██║░░██║░░░██║░░░██╔══╝░░
╚█████╔╝╚█████╔╝██████╔╝███████╗██╔╝╚██╗██████╦╝╚█████╔╝░░░██║░░░███████╗
░╚════╝░░╚════╝░╚═════╝░╚══════╝╚═╝░░╚═╝╚═════╝░░╚════╝░░░░╚═╝░░░╚══════╝
                                          
[18-Sep-24 14:20:44 - INFO] - root - Stop signal received (SIGINT). Exiting...
[18-Sep-24 14:20:48 - INFO] - bot - Bot stopped.
[18-Sep-24 14:21:02 - INFO] - bot - Bot Running..!

Created by 
https://t.me/CodeXBotz
[18-Sep-24 14:21:02 - INFO] - bot -  

       
░█████╗░░█████╗░██████╗░███████╗██╗░░██╗██████╗░░█████╗░████████╗███████╗
██╔══██╗██╔══██╗██╔══██╗██╔════╝╚██╗██╔╝██╔══██╗██╔══██╗╚══██╔══╝╚════██║
██║░░╚═╝██║░░██║██║░░██║█████╗░░░╚███╔╝░██████╦╝██║░░██║░░░██║░░░░░███╔═╝
██║░░██╗██║░░██║██║░░██║██╔══╝░░░██╔██╗░██╔══██╗██║░░██║░░░██║░░░██╔══╝░░
╚█████╔╝╚█████╔╝██████╔╝███████╗██╔╝╚██╗██████╦╝╚█████╔╝░░░██║░░░███████╗
░╚════╝░░╚════╝░╚═════╝░╚══════╝╚═╝░░╚═╝╚═════╝░░╚════╝░░░░╚═╝░░░╚══════╝
                                          
[18-Sep-24 14:37:21 - INFO] - root - Stop signal received (SIGINT). Exiting...
[18-Sep-24 14:37:25 - INFO] - bot - Bot stopped.
[18-Sep-24 14:44:47 - INFO] - bot - Bot Running..!

Created by 
https://t.me/CodeXBotz
[18-Sep-24 14:44:47 - INFO] - bot -  

       
░█████╗░░█████╗░██████╗░███████╗██╗░░██╗██████╗░░█████╗░████████╗███████╗
██╔══██╗██╔══██╗██╔══██╗██╔════╝╚██╗██╔╝██╔══██╗██╔══██╗╚══██╔══╝╚════██║
██║░░╚═╝██║░░██║██║░░██║█████╗░░░╚███╔╝░██████╦╝██║░░██║░░░██║░░░░░███╔═╝
██║░░██╗██║░░██║██║░░██║██╔══╝░░░██╔██╗░██╔══██╗██║░░██║░░░██║░░░██╔══╝░░
╚█████╔╝╚█████╔╝██████╔╝███████╗██╔╝╚██╗██████╦╝╚█████╔╝░░░██║░░░███████╗
░╚════╝░░╚════╝░╚═════╝░╚══════╝╚═╝░░╚═╝╚═════╝░░╚════╝░░░░╚═╝░░░╚══════╝
                                          
[18-Sep-24 14:45:04 - ERROR] - pyrogram.dispatcher - name 'FORCE_SUB_CHANNELS' is not defined
Traceback (most recent call last):
  File "/home/adithyan/.local/lib/python3.10/site-packages/pyrogram/dispatcher.py", line 317, in handler_worker
    await self.loop.run_in_executor(
  File "/usr/lib/python3.10/concurrent/futures/thread.py", line 58, in run
    result = self.fn(*self.args, **self.kwargs)
  File "/home/adithyan/.local/lib/python3.10/site-packages/pyrogram/sync.py", line 78, in async_to_sync_wrap
    return asyncio.run_coroutine_threadsafe(coroutine, main_loop).result()
  File "/usr/lib/python3.10/concurrent/futures/_base.py", line 458, in result
    return self.__get_result()
  File "/usr/lib/python3.10/concurrent/futures/_base.py", line 403, in __get_result
    raise self._exception
  File "/home/adithyan/.local/lib/python3.10/site-packages/pyromod/listen/message_handler.py", line 98, in resolve_future_or_callback
    await self.original_callback(client, message, *args)
  File "/home/adithyan/File-Sharing-Bot/plugins/start.py", line 124, in not_joined
    for channel in FORCE_SUB_CHANNELS:
NameError: name 'FORCE_SUB_CHANNELS' is not defined
[18-Sep-24 14:45:06 - ERROR] - pyrogram.dispatcher - name 'FORCE_SUB_CHANNELS' is not defined
Traceback (most recent call last):
  File "/home/adithyan/.local/lib/python3.10/site-packages/pyrogram/dispatcher.py", line 317, in handler_worker
    await self.loop.run_in_executor(
  File "/usr/lib/python3.10/concurrent/futures/thread.py", line 58, in run
    result = self.fn(*self.args, **self.kwargs)
  File "/home/adithyan/.local/lib/python3.10/site-packages/pyrogram/sync.py", line 78, in async_to_sync_wrap
    return asyncio.run_coroutine_threadsafe(coroutine, main_loop).result()
  File "/usr/lib/python3.10/concurrent/futures/_base.py", line 458, in result
    return self.__get_result()
  File "/usr/lib/python3.10/concurrent/futures/_base.py", line 403, in __get_result
    raise self._exception
  File "/home/adithyan/.local/lib/python3.10/site-packages/pyromod/listen/message_handler.py", line 98, in resolve_future_or_callback
    await self.original_callback(client, message, *args)
  File "/home/adithyan/File-Sharing-Bot/plugins/start.py", line 124, in not_joined
    for channel in FORCE_SUB_CHANNELS:
NameError: name 'FORCE_SUB_CHANNELS' is not defined
[18-Sep-24 14:45:51 - INFO] - root - Stop signal received (SIGINT). Exiting...
[18-Sep-24 14:45:51 - INFO] - root - Stop signal received (SIGINT). Exiting...
[18-Sep-24 14:45:51 - INFO] - root - Stop signal received (SIGINT). Exiting...
[18-Sep-24 14:45:55 - INFO] - bot - Bot stopped.
[18-Sep-24 14:46:04 - INFO] - bot - Bot Running..!

Created by 
https://t.me/CodeXBotz
[18-Sep-24 14:46:04 - INFO] - bot -  

       
░█████╗░░█████╗░██████╗░███████╗██╗░░██╗██████╗░░█████╗░████████╗███████╗
██╔══██╗██╔══██╗██╔══██╗██╔════╝╚██╗██╔╝██╔══██╗██╔══██╗╚══██╔══╝╚════██║
██║░░╚═╝██║░░██║██║░░██║█████╗░░░╚███╔╝░██████╦╝██║░░██║░░░██║░░░░░███╔═╝
██║░░██╗██║░░██║██║░░██║██╔══╝░░░██╔██╗░██╔══██╗██║░░██║░░░██║░░░██╔══╝░░
╚█████╔╝╚█████╔╝██████╔╝███████╗██╔╝╚██╗██████╦╝╚█████╔╝░░░██║░░░███████╗
░╚════╝░░╚════╝░╚═════╝░╚══════╝╚═╝░░╚═╝╚═════╝░░╚════╝░░░░╚═╝░░░╚══════╝
                                          
[18-Sep-24 14:49:25 - ERROR] - pyrogram.dispatcher - Telegram says: [400 PEER_ID_INVALID] - The peer id being used is invalid or not known yet. Make sure you meet the peer before interacting with it (caused by "messages.ExportChatInvite")
Traceback (most recent call last):
  File "/home/adithyan/.local/lib/python3.10/site-packages/pyrogram/dispatcher.py", line 317, in handler_worker
    await self.loop.run_in_executor(
  File "/usr/lib/python3.10/concurrent/futures/thread.py", line 58, in run
    result = self.fn(*self.args, **self.kwargs)
  File "/home/adithyan/.local/lib/python3.10/site-packages/pyrogram/sync.py", line 78, in async_to_sync_wrap
    return asyncio.run_coroutine_threadsafe(coroutine, main_loop).result()
  File "/usr/lib/python3.10/concurrent/futures/_base.py", line 458, in result
    return self.__get_result()
  File "/usr/lib/python3.10/concurrent/futures/_base.py", line 403, in __get_result
    raise self._exception
  File "/home/adithyan/.local/lib/python3.10/site-packages/pyromod/listen/message_handler.py", line 98, in resolve_future_or_callback
    await self.original_callback(client, message, *args)
  File "/home/adithyan/File-Sharing-Bot/plugins/start.py", line 126, in not_joined
    invite_link = await chat.export_invite_link()
  File "/home/adithyan/.local/lib/python3.10/site-packages/pyrogram/types/user_and_chats/chat.py", line 1161, in export_invite_link
    return await self._client.export_chat_invite_link(self.id)
  File "/home/adithyan/.local/lib/python3.10/site-packages/pyrogram/methods/invite_links/export_chat_invite_link.py", line 58, in export_chat_invite_link
    r = await self.invoke(
  File "/home/adithyan/.local/lib/python3.10/site-packages/pyrogram/methods/advanced/invoke.py", line 94, in invoke
    r = await session.invoke(
  File "/home/adithyan/.local/lib/python3.10/site-packages/pyrogram/session/session.py", line 406, in invoke
    return await self.send(query, timeout=timeout)
  File "/home/adithyan/.local/lib/python3.10/site-packages/pyrogram/session/session.py", line 374, in send
    RPCError.raise_it(result, type(data))
  File "/home/adithyan/.local/lib/python3.10/site-packages/pyrogram/errors/rpc_error.py", line 91, in raise_it
    raise getattr(
pyrogram.errors.exceptions.bad_request_400.PeerIdInvalid: Telegram says: [400 PEER_ID_INVALID] - The peer id being used is invalid or not known yet. Make sure you meet the peer before interacting with it (caused by "messages.ExportChatInvite")
[18-Sep-24 14:49:41 - INFO] - root - Stop signal received (SIGINT). Exiting...
[18-Sep-24 14:49:43 - INFO] - bot - Bot stopped.
[18-Sep-24 14:50:09 - WARNING] - bot - Error in channel -4577356879: Telegram says: [400 PEER_ID_INVALID] - The peer id being used is invalid or not known yet. Make sure you meet the peer before interacting with it (caused by "messages.ExportChatInvite")
[18-Sep-24 14:50:09 - WARNING] - bot - Please check the FORCE_SUB_CHANNELS value and make sure the Bot is Admin in all channels with Invite Users via Link Permission.
[18-Sep-24 14:50:09 - INFO] - bot - Bot Running..!

Created by 
https://t.me/CodeXBotz
[18-Sep-24 14:50:09 - INFO] - bot -  

       
░█████╗░░█████╗░██████╗░███████╗██╗░░██╗██████╗░░█████╗░████████╗███████╗
██╔══██╗██╔══██╗██╔══██╗██╔════╝╚██╗██╔╝██╔══██╗██╔══██╗╚══██╔══╝╚════██║
██║░░╚═╝██║░░██║██║░░██║█████╗░░░╚███╔╝░██████╦╝██║░░██║░░░██║░░░░░███╔═╝
██║░░██╗██║░░██║██║░░██║██╔══╝░░░██╔██╗░██╔══██╗██║░░██║░░░██║░░░██╔══╝░░
╚█████╔╝╚█████╔╝██████╔╝███████╗██╔╝╚██╗██████╦╝╚█████╔╝░░░██║░░░███████╗
░╚════╝░░╚════╝░╚═════╝░╚══════╝╚═╝░░╚═╝╚═════╝░░╚════╝░░░░╚═╝░░░╚══════╝
                                          
[18-Sep-24 14:50:10 - ERROR] - pyrogram.dispatcher - Telegram says: [400 PEER_ID_INVALID] - The peer id being used is invalid or not known yet. Make sure you meet the peer before interacting with it (caused by "messages.ExportChatInvite")
Traceback (most recent call last):
  File "/home/adithyan/.local/lib/python3.10/site-packages/pyrogram/dispatcher.py", line 317, in handler_worker
    await self.loop.run_in_executor(
  File "/usr/lib/python3.10/concurrent/futures/thread.py", line 58, in run
    result = self.fn(*self.args, **self.kwargs)
  File "/home/adithyan/.local/lib/python3.10/site-packages/pyrogram/sync.py", line 78, in async_to_sync_wrap
    return asyncio.run_coroutine_threadsafe(coroutine, main_loop).result()
  File "/usr/lib/python3.10/concurrent/futures/_base.py", line 458, in result
    return self.__get_result()
  File "/usr/lib/python3.10/concurrent/futures/_base.py", line 403, in __get_result
    raise self._exception
  File "/home/adithyan/.local/lib/python3.10/site-packages/pyromod/listen/message_handler.py", line 98, in resolve_future_or_callback
    await self.original_callback(client, message, *args)
  File "/home/adithyan/File-Sharing-Bot/plugins/start.py", line 126, in not_joined
    invite_link = await chat.export_invite_link()
  File "/home/adithyan/.local/lib/python3.10/site-packages/pyrogram/types/user_and_chats/chat.py", line 1161, in export_invite_link
    return await self._client.export_chat_invite_link(self.id)
  File "/home/adithyan/.local/lib/python3.10/site-packages/pyrogram/methods/invite_links/export_chat_invite_link.py", line 58, in export_chat_invite_link
    r = await self.invoke(
  File "/home/adithyan/.local/lib/python3.10/site-packages/pyrogram/methods/advanced/invoke.py", line 94, in invoke
    r = await session.invoke(
  File "/home/adithyan/.local/lib/python3.10/site-packages/pyrogram/session/session.py", line 406, in invoke
    return await self.send(query, timeout=timeout)
  File "/home/adithyan/.local/lib/python3.10/site-packages/pyrogram/session/session.py", line 374, in send
    RPCError.raise_it(result, type(data))
  File "/home/adithyan/.local/lib/python3.10/site-packages/pyrogram/errors/rpc_error.py", line 91, in raise_it
    raise getattr(
pyrogram.errors.exceptions.bad_request_400.PeerIdInvalid: Telegram says: [400 PEER_ID_INVALID] - The peer id being used is invalid or not known yet. Make sure you meet the peer before interacting with it (caused by "messages.ExportChatInvite")
[18-Sep-24 14:50:33 - ERROR] - pyrogram.dispatcher - 'Bot' object has no attribute 'db_channel'
Traceback (most recent call last):
  File "/home/adithyan/.local/lib/python3.10/site-packages/pyrogram/dispatcher.py", line 317, in handler_worker
    await self.loop.run_in_executor(
  File "/usr/lib/python3.10/concurrent/futures/thread.py", line 58, in run
    result = self.fn(*self.args, **self.kwargs)
  File "/home/adithyan/.local/lib/python3.10/site-packages/pyrogram/sync.py", line 78, in async_to_sync_wrap
    return asyncio.run_coroutine_threadsafe(coroutine, main_loop).result()
  File "/usr/lib/python3.10/concurrent/futures/_base.py", line 458, in result
    return self.__get_result()
  File "/usr/lib/python3.10/concurrent/futures/_base.py", line 403, in __get_result
    raise self._exception
  File "/home/adithyan/.local/lib/python3.10/site-packages/pyromod/listen/message_handler.py", line 98, in resolve_future_or_callback
    await self.original_callback(client, message, *args)
  File "/home/adithyan/File-Sharing-Bot/plugins/channel_post.py", line 48, in new_post
    converted_id = message.id * abs(client.db_channel.id)
AttributeError: 'Bot' object has no attribute 'db_channel'
[18-Sep-24 14:52:02 - ERROR] - pyrogram.dispatcher - 'Bot' object has no attribute 'db_channel'
Traceback (most recent call last):
  File "/home/adithyan/.local/lib/python3.10/site-packages/pyrogram/dispatcher.py", line 317, in handler_worker
    await self.loop.run_in_executor(
  File "/usr/lib/python3.10/concurrent/futures/thread.py", line 58, in run
    result = self.fn(*self.args, **self.kwargs)
  File "/home/adithyan/.local/lib/python3.10/site-packages/pyrogram/sync.py", line 78, in async_to_sync_wrap
    return asyncio.run_coroutine_threadsafe(coroutine, main_loop).result()
  File "/usr/lib/python3.10/concurrent/futures/_base.py", line 458, in result
    return self.__get_result()
  File "/usr/lib/python3.10/concurrent/futures/_base.py", line 403, in __get_result
    raise self._exception
  File "/home/adithyan/.local/lib/python3.10/site-packages/pyromod/listen/message_handler.py", line 98, in resolve_future_or_callback
    await self.original_callback(client, message, *args)
  File "/home/adithyan/File-Sharing-Bot/plugins/link_generator.py", line 16, in batch
    f_msg_id = await get_message_id(client, first_message)
  File "/home/adithyan/File-Sharing-Bot/helper_func.py", line 67, in get_message_id
    if message.forward_from_chat.id == client.db_channel.id:
AttributeError: 'Bot' object has no attribute 'db_channel'
[18-Sep-24 14:52:49 - ERROR] - pyrogram.dispatcher - 'Bot' object has no attribute 'db_channel'
Traceback (most recent call last):
  File "/home/adithyan/.local/lib/python3.10/site-packages/pyrogram/dispatcher.py", line 317, in handler_worker
    await self.loop.run_in_executor(
  File "/usr/lib/python3.10/concurrent/futures/thread.py", line 58, in run
    result = self.fn(*self.args, **self.kwargs)
  File "/home/adithyan/.local/lib/python3.10/site-packages/pyrogram/sync.py", line 78, in async_to_sync_wrap
    return asyncio.run_coroutine_threadsafe(coroutine, main_loop).result()
  File "/usr/lib/python3.10/concurrent/futures/_base.py", line 458, in result
    return self.__get_result()
  File "/usr/lib/python3.10/concurrent/futures/_base.py", line 403, in __get_result
    raise self._exception
  File "/home/adithyan/.local/lib/python3.10/site-packages/pyromod/listen/message_handler.py", line 98, in resolve_future_or_callback
    await self.original_callback(client, message, *args)
  File "/home/adithyan/File-Sharing-Bot/plugins/link_generator.py", line 16, in batch
    f_msg_id = await get_message_id(client, first_message)
  File "/home/adithyan/File-Sharing-Bot/helper_func.py", line 84, in get_message_id
    if channel_id == client.db_channel.username:
AttributeError: 'Bot' object has no attribute 'db_channel'
[18-Sep-24 14:54:22 - INFO] - root - Stop signal received (SIGINT). Exiting...
[18-Sep-24 14:54:23 - INFO] - bot - Bot stopped.
[18-Sep-24 14:54:35 - WARNING] - bot - Error in channel -4577356879: Telegram says: [400 PEER_ID_INVALID] - The peer id being used is invalid or not known yet. Make sure you meet the peer before interacting with it (caused by "messages.ExportChatInvite")
[18-Sep-24 14:54:35 - WARNING] - bot - Please check the FORCE_SUB_CHANNELS value and make sure the Bot is Admin in all channels with Invite Users via Link Permission.
[18-Sep-24 14:54:35 - INFO] - bot - Bot Running..!

Created by 
https://t.me/CodeXBotz
[18-Sep-24 14:54:35 - INFO] - bot -  

       
░█████╗░░█████╗░██████╗░███████╗██╗░░██╗██████╗░░█████╗░████████╗███████╗
██╔══██╗██╔══██╗██╔══██╗██╔════╝╚██╗██╔╝██╔══██╗██╔══██╗╚══██╔══╝╚════██║
██║░░╚═╝██║░░██║██║░░██║█████╗░░░╚███╔╝░██████╦╝██║░░██║░░░██║░░░░░███╔═╝
██║░░██╗██║░░██║██║░░██║██╔══╝░░░██╔██╗░██╔══██╗██║░░██║░░░██║░░░██╔══╝░░
╚█████╔╝╚█████╔╝██████╔╝███████╗██╔╝╚██╗██████╦╝╚█████╔╝░░░██║░░░███████╗
░╚════╝░░╚════╝░╚═════╝░╚══════╝╚═╝░░╚═╝╚═════╝░░╚════╝░░░░╚═╝░░░╚══════╝
                                          
[18-Sep-24 14:56:27 - ERROR] - pyrogram.dispatcher - 'Bot' object has no attribute 'db_channel'
Traceback (most recent call last):
  File "/home/adithyan/.local/lib/python3.10/site-packages/pyrogram/dispatcher.py", line 317, in handler_worker
    await self.loop.run_in_executor(
  File "/usr/lib/python3.10/concurrent/futures/thread.py", line 58, in run
    result = self.fn(*self.args, **self.kwargs)
  File "/home/adithyan/.local/lib/python3.10/site-packages/pyrogram/sync.py", line 78, in async_to_sync_wrap
    return asyncio.run_coroutine_threadsafe(coroutine, main_loop).result()
  File "/usr/lib/python3.10/concurrent/futures/_base.py", line 458, in result
    return self.__get_result()
  File "/usr/lib/python3.10/concurrent/futures/_base.py", line 403, in __get_result
    raise self._exception
  File "/home/adithyan/.local/lib/python3.10/site-packages/pyromod/listen/message_handler.py", line 98, in resolve_future_or_callback
    await self.original_callback(client, message, *args)
  File "/home/adithyan/File-Sharing-Bot/plugins/channel_post.py", line 48, in new_post
    converted_id = message.id * abs(client.db_channel.id)
AttributeError: 'Bot' object has no attribute 'db_channel'
[18-Sep-24 14:56:28 - ERROR] - pyrogram.dispatcher - Telegram says: [400 PEER_ID_INVALID] - The peer id being used is invalid or not known yet. Make sure you meet the peer before interacting with it (caused by "messages.ExportChatInvite")
Traceback (most recent call last):
  File "/home/adithyan/.local/lib/python3.10/site-packages/pyrogram/dispatcher.py", line 317, in handler_worker
    await self.loop.run_in_executor(
  File "/usr/lib/python3.10/concurrent/futures/thread.py", line 58, in run
    result = self.fn(*self.args, **self.kwargs)
  File "/home/adithyan/.local/lib/python3.10/site-packages/pyrogram/sync.py", line 78, in async_to_sync_wrap
    return asyncio.run_coroutine_threadsafe(coroutine, main_loop).result()
  File "/usr/lib/python3.10/concurrent/futures/_base.py", line 458, in result
    return self.__get_result()
  File "/usr/lib/python3.10/concurrent/futures/_base.py", line 403, in __get_result
    raise self._exception
  File "/home/adithyan/.local/lib/python3.10/site-packages/pyromod/listen/message_handler.py", line 98, in resolve_future_or_callback
    await self.original_callback(client, message, *args)
  File "/home/adithyan/File-Sharing-Bot/plugins/start.py", line 126, in not_joined
    invite_link = await chat.export_invite_link()
  File "/home/adithyan/.local/lib/python3.10/site-packages/pyrogram/types/user_and_chats/chat.py", line 1161, in export_invite_link
    return await self._client.export_chat_invite_link(self.id)
  File "/home/adithyan/.local/lib/python3.10/site-packages/pyrogram/methods/invite_links/export_chat_invite_link.py", line 58, in export_chat_invite_link
    r = await self.invoke(
  File "/home/adithyan/.local/lib/python3.10/site-packages/pyrogram/methods/advanced/invoke.py", line 94, in invoke
    r = await session.invoke(
  File "/home/adithyan/.local/lib/python3.10/site-packages/pyrogram/session/session.py", line 406, in invoke
    return await self.send(query, timeout=timeout)
  File "/home/adithyan/.local/lib/python3.10/site-packages/pyrogram/session/session.py", line 374, in send
    RPCError.raise_it(result, type(data))
  File "/home/adithyan/.local/lib/python3.10/site-packages/pyrogram/errors/rpc_error.py", line 91, in raise_it
    raise getattr(
pyrogram.errors.exceptions.bad_request_400.PeerIdInvalid: Telegram says: [400 PEER_ID_INVALID] - The peer id being used is invalid or not known yet. Make sure you meet the peer before interacting with it (caused by "messages.ExportChatInvite")
[18-Sep-24 14:56:28 - ERROR] - pyrogram.dispatcher - 'Bot' object has no attribute 'db_channel'
Traceback (most recent call last):
  File "/home/adithyan/.local/lib/python3.10/site-packages/pyrogram/dispatcher.py", line 317, in handler_worker
    await self.loop.run_in_executor(
  File "/usr/lib/python3.10/concurrent/futures/thread.py", line 58, in run
    result = self.fn(*self.args, **self.kwargs)
  File "/home/adithyan/.local/lib/python3.10/site-packages/pyrogram/sync.py", line 78, in async_to_sync_wrap
    return asyncio.run_coroutine_threadsafe(coroutine, main_loop).result()
  File "/usr/lib/python3.10/concurrent/futures/_base.py", line 458, in result
    return self.__get_result()
  File "/usr/lib/python3.10/concurrent/futures/_base.py", line 403, in __get_result
    raise self._exception
  File "/home/adithyan/.local/lib/python3.10/site-packages/pyromod/listen/message_handler.py", line 98, in resolve_future_or_callback
    await self.original_callback(client, message, *args)
  File "/home/adithyan/File-Sharing-Bot/plugins/channel_post.py", line 48, in new_post
    converted_id = message.id * abs(client.db_channel.id)
AttributeError: 'Bot' object has no attribute 'db_channel'
[18-Sep-24 14:56:29 - ERROR] - pyrogram.dispatcher - 'Bot' object has no attribute 'db_channel'
Traceback (most recent call last):
  File "/home/adithyan/.local/lib/python3.10/site-packages/pyrogram/dispatcher.py", line 317, in handler_worker
    await self.loop.run_in_executor(
  File "/usr/lib/python3.10/concurrent/futures/thread.py", line 58, in run
    result = self.fn(*self.args, **self.kwargs)
  File "/home/adithyan/.local/lib/python3.10/site-packages/pyrogram/sync.py", line 78, in async_to_sync_wrap
    return asyncio.run_coroutine_threadsafe(coroutine, main_loop).result()
  File "/usr/lib/python3.10/concurrent/futures/_base.py", line 458, in result
    return self.__get_result()
  File "/usr/lib/python3.10/concurrent/futures/_base.py", line 403, in __get_result
    raise self._exception
  File "/home/adithyan/.local/lib/python3.10/site-packages/pyromod/listen/message_handler.py", line 98, in resolve_future_or_callback
    await self.original_callback(client, message, *args)
  File "/home/adithyan/File-Sharing-Bot/plugins/channel_post.py", line 48, in new_post
    converted_id = message.id * abs(client.db_channel.id)
AttributeError: 'Bot' object has no attribute 'db_channel'
[18-Sep-24 14:56:29 - ERROR] - pyrogram.dispatcher - 'Bot' object has no attribute 'db_channel'
Traceback (most recent call last):
  File "/home/adithyan/.local/lib/python3.10/site-packages/pyrogram/dispatcher.py", line 317, in handler_worker
    await self.loop.run_in_executor(
  File "/usr/lib/python3.10/concurrent/futures/thread.py", line 58, in run
    result = self.fn(*self.args, **self.kwargs)
  File "/home/adithyan/.local/lib/python3.10/site-packages/pyrogram/sync.py", line 78, in async_to_sync_wrap
    return asyncio.run_coroutine_threadsafe(coroutine, main_loop).result()
  File "/usr/lib/python3.10/concurrent/futures/_base.py", line 458, in result
    return self.__get_result()
  File "/usr/lib/python3.10/concurrent/futures/_base.py", line 403, in __get_result
    raise self._exception
  File "/home/adithyan/.local/lib/python3.10/site-packages/pyromod/listen/message_handler.py", line 98, in resolve_future_or_callback
    await self.original_callback(client, message, *args)
  File "/home/adithyan/File-Sharing-Bot/plugins/channel_post.py", line 48, in new_post
    converted_id = message.id * abs(client.db_channel.id)
AttributeError: 'Bot' object has no attribute 'db_channel'
[18-Sep-24 14:56:30 - ERROR] - pyrogram.dispatcher - 'Bot' object has no attribute 'db_channel'
Traceback (most recent call last):
  File "/home/adithyan/.local/lib/python3.10/site-packages/pyrogram/dispatcher.py", line 317, in handler_worker
    await self.loop.run_in_executor(
  File "/usr/lib/python3.10/concurrent/futures/thread.py", line 58, in run
    result = self.fn(*self.args, **self.kwargs)
  File "/home/adithyan/.local/lib/python3.10/site-packages/pyrogram/sync.py", line 78, in async_to_sync_wrap
    return asyncio.run_coroutine_threadsafe(coroutine, main_loop).result()
  File "/usr/lib/python3.10/concurrent/futures/_base.py", line 458, in result
    return self.__get_result()
  File "/usr/lib/python3.10/concurrent/futures/_base.py", line 403, in __get_result
    raise self._exception
  File "/home/adithyan/.local/lib/python3.10/site-packages/pyromod/listen/message_handler.py", line 98, in resolve_future_or_callback
    await self.original_callback(client, message, *args)
  File "/home/adithyan/File-Sharing-Bot/plugins/channel_post.py", line 48, in new_post
    converted_id = message.id * abs(client.db_channel.id)
AttributeError: 'Bot' object has no attribute 'db_channel'
[18-Sep-24 14:56:30 - ERROR] - pyrogram.dispatcher - 'Bot' object has no attribute 'db_channel'
Traceback (most recent call last):
  File "/home/adithyan/.local/lib/python3.10/site-packages/pyrogram/dispatcher.py", line 317, in handler_worker
    await self.loop.run_in_executor(
  File "/usr/lib/python3.10/concurrent/futures/thread.py", line 58, in run
    result = self.fn(*self.args, **self.kwargs)
  File "/home/adithyan/.local/lib/python3.10/site-packages/pyrogram/sync.py", line 78, in async_to_sync_wrap
    return asyncio.run_coroutine_threadsafe(coroutine, main_loop).result()
  File "/usr/lib/python3.10/concurrent/futures/_base.py", line 458, in result
    return self.__get_result()
  File "/usr/lib/python3.10/concurrent/futures/_base.py", line 403, in __get_result
    raise self._exception
  File "/home/adithyan/.local/lib/python3.10/site-packages/pyromod/listen/message_handler.py", line 98, in resolve_future_or_callback
    await self.original_callback(client, message, *args)
  File "/home/adithyan/File-Sharing-Bot/plugins/channel_post.py", line 48, in new_post
    converted_id = message.id * abs(client.db_channel.id)
AttributeError: 'Bot' object has no attribute 'db_channel'
[18-Sep-24 14:56:31 - ERROR] - pyrogram.dispatcher - 'Bot' object has no attribute 'db_channel'
Traceback (most recent call last):
  File "/home/adithyan/.local/lib/python3.10/site-packages/pyrogram/dispatcher.py", line 317, in handler_worker
    await self.loop.run_in_executor(
  File "/usr/lib/python3.10/concurrent/futures/thread.py", line 58, in run
    result = self.fn(*self.args, **self.kwargs)
  File "/home/adithyan/.local/lib/python3.10/site-packages/pyrogram/sync.py", line 78, in async_to_sync_wrap
    return asyncio.run_coroutine_threadsafe(coroutine, main_loop).result()
  File "/usr/lib/python3.10/concurrent/futures/_base.py", line 458, in result
    return self.__get_result()
  File "/usr/lib/python3.10/concurrent/futures/_base.py", line 403, in __get_result
    raise self._exception
  File "/home/adithyan/.local/lib/python3.10/site-packages/pyromod/listen/message_handler.py", line 98, in resolve_future_or_callback
    await self.original_callback(client, message, *args)
  File "/home/adithyan/File-Sharing-Bot/plugins/channel_post.py", line 48, in new_post
    converted_id = message.id * abs(client.db_channel.id)
AttributeError: 'Bot' object has no attribute 'db_channel'
[18-Sep-24 14:56:32 - ERROR] - pyrogram.dispatcher - 'Bot' object has no attribute 'db_channel'
Traceback (most recent call last):
  File "/home/adithyan/.local/lib/python3.10/site-packages/pyrogram/dispatcher.py", line 317, in handler_worker
    await self.loop.run_in_executor(
  File "/usr/lib/python3.10/concurrent/futures/thread.py", line 58, in run
    result = self.fn(*self.args, **self.kwargs)
  File "/home/adithyan/.local/lib/python3.10/site-packages/pyrogram/sync.py", line 78, in async_to_sync_wrap
    return asyncio.run_coroutine_threadsafe(coroutine, main_loop).result()
  File "/usr/lib/python3.10/concurrent/futures/_base.py", line 458, in result
    return self.__get_result()
  File "/usr/lib/python3.10/concurrent/futures/_base.py", line 403, in __get_result
    raise self._exception
  File "/home/adithyan/.local/lib/python3.10/site-packages/pyromod/listen/message_handler.py", line 98, in resolve_future_or_callback
    await self.original_callback(client, message, *args)
  File "/home/adithyan/File-Sharing-Bot/plugins/channel_post.py", line 48, in new_post
    converted_id = message.id * abs(client.db_channel.id)
AttributeError: 'Bot' object has no attribute 'db_channel'
[18-Sep-24 14:56:33 - ERROR] - pyrogram.dispatcher - Telegram says: [400 PEER_ID_INVALID] - The peer id being used is invalid or not known yet. Make sure you meet the peer before interacting with it (caused by "messages.ExportChatInvite")
Traceback (most recent call last):
  File "/home/adithyan/.local/lib/python3.10/site-packages/pyrogram/dispatcher.py", line 317, in handler_worker
    await self.loop.run_in_executor(
  File "/usr/lib/python3.10/concurrent/futures/thread.py", line 58, in run
    result = self.fn(*self.args, **self.kwargs)
  File "/home/adithyan/.local/lib/python3.10/site-packages/pyrogram/sync.py", line 78, in async_to_sync_wrap
    return asyncio.run_coroutine_threadsafe(coroutine, main_loop).result()
  File "/usr/lib/python3.10/concurrent/futures/_base.py", line 458, in result
    return self.__get_result()
  File "/usr/lib/python3.10/concurrent/futures/_base.py", line 403, in __get_result
    raise self._exception
  File "/home/adithyan/.local/lib/python3.10/site-packages/pyromod/listen/message_handler.py", line 98, in resolve_future_or_callback
    await self.original_callback(client, message, *args)
  File "/home/adithyan/File-Sharing-Bot/plugins/start.py", line 126, in not_joined
    invite_link = await chat.export_invite_link()
  File "/home/adithyan/.local/lib/python3.10/site-packages/pyrogram/types/user_and_chats/chat.py", line 1161, in export_invite_link
    return await self._client.export_chat_invite_link(self.id)
  File "/home/adithyan/.local/lib/python3.10/site-packages/pyrogram/methods/invite_links/export_chat_invite_link.py", line 58, in export_chat_invite_link
    r = await self.invoke(
  File "/home/adithyan/.local/lib/python3.10/site-packages/pyrogram/methods/advanced/invoke.py", line 94, in invoke
    r = await session.invoke(
  File "/home/adithyan/.local/lib/python3.10/site-packages/pyrogram/session/session.py", line 406, in invoke
    return await self.send(query, timeout=timeout)
  File "/home/adithyan/.local/lib/python3.10/site-packages/pyrogram/session/session.py", line 374, in send
    RPCError.raise_it(result, type(data))
  File "/home/adithyan/.local/lib/python3.10/site-packages/pyrogram/errors/rpc_error.py", line 91, in raise_it
    raise getattr(
pyrogram.errors.exceptions.bad_request_400.PeerIdInvalid: Telegram says: [400 PEER_ID_INVALID] - The peer id being used is invalid or not known yet. Make sure you meet the peer before interacting with it (caused by "messages.ExportChatInvite")
[18-Sep-24 14:56:41 - INFO] - root - Stop signal received (SIGINT). Exiting...
[18-Sep-24 14:56:44 - INFO] - bot - Bot stopped.
[18-Sep-24 14:57:33 - WARNING] - bot - Error in channel -4577356879: Telegram says: [400 PEER_ID_INVALID] - The peer id being used is invalid or not known yet. Make sure you meet the peer before interacting with it (caused by "messages.ExportChatInvite")
[18-Sep-24 14:57:33 - WARNING] - bot - Please check the FORCE_SUB_CHANNELS value and make sure the Bot is Admin in all channels with Invite Users via Link Permission.
[18-Sep-24 14:57:34 - INFO] - bot - Bot Running..!

Created by 
https://t.me/CodeXBotz
[18-Sep-24 14:57:34 - INFO] - bot -  

       
░█████╗░░█████╗░██████╗░███████╗██╗░░██╗██████╗░░█████╗░████████╗███████╗
██╔══██╗██╔══██╗██╔══██╗██╔════╝╚██╗██╔╝██╔══██╗██╔══██╗╚══██╔══╝╚════██║
██║░░╚═╝██║░░██║██║░░██║█████╗░░░╚███╔╝░██████╦╝██║░░██║░░░██║░░░░░███╔═╝
██║░░██╗██║░░██║██║░░██║██╔══╝░░░██╔██╗░██╔══██╗██║░░██║░░░██║░░░██╔══╝░░
╚█████╔╝╚█████╔╝██████╔╝███████╗██╔╝╚██╗██████╦╝╚█████╔╝░░░██║░░░███████╗
░╚════╝░░╚════╝░╚═════╝░╚══════╝╚═╝░░╚═╝╚═════╝░░╚════╝░░░░╚═╝░░░╚══════╝
                                          
[18-Sep-24 14:57:40 - ERROR] - pyrogram.dispatcher - Telegram says: [400 PEER_ID_INVALID] - The peer id being used is invalid or not known yet. Make sure you meet the peer before interacting with it (caused by "messages.ExportChatInvite")
Traceback (most recent call last):
  File "/home/adithyan/.local/lib/python3.10/site-packages/pyrogram/dispatcher.py", line 317, in handler_worker
    await self.loop.run_in_executor(
  File "/usr/lib/python3.10/concurrent/futures/thread.py", line 58, in run
    result = self.fn(*self.args, **self.kwargs)
  File "/home/adithyan/.local/lib/python3.10/site-packages/pyrogram/sync.py", line 78, in async_to_sync_wrap
    return asyncio.run_coroutine_threadsafe(coroutine, main_loop).result()
  File "/usr/lib/python3.10/concurrent/futures/_base.py", line 458, in result
    return self.__get_result()
  File "/usr/lib/python3.10/concurrent/futures/_base.py", line 403, in __get_result
    raise self._exception
  File "/home/adithyan/.local/lib/python3.10/site-packages/pyromod/listen/message_handler.py", line 98, in resolve_future_or_callback
    await self.original_callback(client, message, *args)
  File "/home/adithyan/File-Sharing-Bot/plugins/start.py", line 126, in not_joined
    invite_link = await chat.export_invite_link()
  File "/home/adithyan/.local/lib/python3.10/site-packages/pyrogram/types/user_and_chats/chat.py", line 1161, in export_invite_link
    return await self._client.export_chat_invite_link(self.id)
  File "/home/adithyan/.local/lib/python3.10/site-packages/pyrogram/methods/invite_links/export_chat_invite_link.py", line 58, in export_chat_invite_link
    r = await self.invoke(
  File "/home/adithyan/.local/lib/python3.10/site-packages/pyrogram/methods/advanced/invoke.py", line 94, in invoke
    r = await session.invoke(
  File "/home/adithyan/.local/lib/python3.10/site-packages/pyrogram/session/session.py", line 406, in invoke
    return await self.send(query, timeout=timeout)
  File "/home/adithyan/.local/lib/python3.10/site-packages/pyrogram/session/session.py", line 374, in send
    RPCError.raise_it(result, type(data))
  File "/home/adithyan/.local/lib/python3.10/site-packages/pyrogram/errors/rpc_error.py", line 91, in raise_it
    raise getattr(
pyrogram.errors.exceptions.bad_request_400.PeerIdInvalid: Telegram says: [400 PEER_ID_INVALID] - The peer id being used is invalid or not known yet. Make sure you meet the peer before interacting with it (caused by "messages.ExportChatInvite")
[18-Sep-24 14:57:45 - ERROR] - pyrogram.dispatcher - Telegram says: [400 PEER_ID_INVALID] - The peer id being used is invalid or not known yet. Make sure you meet the peer before interacting with it (caused by "messages.ExportChatInvite")
Traceback (most recent call last):
  File "/home/adithyan/.local/lib/python3.10/site-packages/pyrogram/dispatcher.py", line 317, in handler_worker
    await self.loop.run_in_executor(
  File "/usr/lib/python3.10/concurrent/futures/thread.py", line 58, in run
    result = self.fn(*self.args, **self.kwargs)
  File "/home/adithyan/.local/lib/python3.10/site-packages/pyrogram/sync.py", line 78, in async_to_sync_wrap
    return asyncio.run_coroutine_threadsafe(coroutine, main_loop).result()
  File "/usr/lib/python3.10/concurrent/futures/_base.py", line 458, in result
    return self.__get_result()
  File "/usr/lib/python3.10/concurrent/futures/_base.py", line 403, in __get_result
    raise self._exception
  File "/home/adithyan/.local/lib/python3.10/site-packages/pyromod/listen/message_handler.py", line 98, in resolve_future_or_callback
    await self.original_callback(client, message, *args)
  File "/home/adithyan/File-Sharing-Bot/plugins/start.py", line 126, in not_joined
    invite_link = await chat.export_invite_link()
  File "/home/adithyan/.local/lib/python3.10/site-packages/pyrogram/types/user_and_chats/chat.py", line 1161, in export_invite_link
    return await self._client.export_chat_invite_link(self.id)
  File "/home/adithyan/.local/lib/python3.10/site-packages/pyrogram/methods/invite_links/export_chat_invite_link.py", line 58, in export_chat_invite_link
    r = await self.invoke(
  File "/home/adithyan/.local/lib/python3.10/site-packages/pyrogram/methods/advanced/invoke.py", line 94, in invoke
    r = await session.invoke(
  File "/home/adithyan/.local/lib/python3.10/site-packages/pyrogram/session/session.py", line 406, in invoke
    return await self.send(query, timeout=timeout)
  File "/home/adithyan/.local/lib/python3.10/site-packages/pyrogram/session/session.py", line 374, in send
    RPCError.raise_it(result, type(data))
  File "/home/adithyan/.local/lib/python3.10/site-packages/pyrogram/errors/rpc_error.py", line 91, in raise_it
    raise getattr(
pyrogram.errors.exceptions.bad_request_400.PeerIdInvalid: Telegram says: [400 PEER_ID_INVALID] - The peer id being used is invalid or not known yet. Make sure you meet the peer before interacting with it (caused by "messages.ExportChatInvite")
[18-Sep-24 14:58:43 - ERROR] - pyrogram.dispatcher - 'Bot' object has no attribute 'db_channel'
Traceback (most recent call last):
  File "/home/adithyan/.local/lib/python3.10/site-packages/pyrogram/dispatcher.py", line 317, in handler_worker
    await self.loop.run_in_executor(
  File "/usr/lib/python3.10/concurrent/futures/thread.py", line 58, in run
    result = self.fn(*self.args, **self.kwargs)
  File "/home/adithyan/.local/lib/python3.10/site-packages/pyrogram/sync.py", line 78, in async_to_sync_wrap
    return asyncio.run_coroutine_threadsafe(coroutine, main_loop).result()
  File "/usr/lib/python3.10/concurrent/futures/_base.py", line 458, in result
    return self.__get_result()
  File "/usr/lib/python3.10/concurrent/futures/_base.py", line 403, in __get_result
    raise self._exception
  File "/home/adithyan/.local/lib/python3.10/site-packages/pyromod/listen/message_handler.py", line 98, in resolve_future_or_callback
    await self.original_callback(client, message, *args)
  File "/home/adithyan/File-Sharing-Bot/plugins/channel_post.py", line 48, in new_post
    converted_id = message.id * abs(client.db_channel.id)
AttributeError: 'Bot' object has no attribute 'db_channel'
[18-Sep-24 14:59:14 - INFO] - root - Stop signal received (SIGINT). Exiting...
[18-Sep-24 14:59:14 - INFO] - root - Stop signal received (SIGINT). Exiting...
[18-Sep-24 14:59:14 - INFO] - root - Stop signal received (SIGINT). Exiting...
[18-Sep-24 14:59:15 - INFO] - root - Stop signal received (SIGINT). Exiting...
[18-Sep-24 14:59:17 - INFO] - bot - Bot stopped.
[18-Sep-24 14:59:32 - INFO] - bot - Bot Running..!

Created by 
https://t.me/CodeXBotz
[18-Sep-24 14:59:32 - INFO] - bot -  

       
░█████╗░░█████╗░██████╗░███████╗██╗░░██╗██████╗░░█████╗░████████╗███████╗
██╔══██╗██╔══██╗██╔══██╗██╔════╝╚██╗██╔╝██╔══██╗██╔══██╗╚══██╔══╝╚════██║
██║░░╚═╝██║░░██║██║░░██║█████╗░░░╚███╔╝░██████╦╝██║░░██║░░░██║░░░░░███╔═╝
██║░░██╗██║░░██║██║░░██║██╔══╝░░░██╔██╗░██╔══██╗██║░░██║░░░██║░░░██╔══╝░░
╚█████╔╝╚█████╔╝██████╔╝███████╗██╔╝╚██╗██████╦╝╚█████╔╝░░░██║░░░███████╗
░╚════╝░░╚════╝░╚═════╝░╚══════╝╚═╝░░╚═╝╚═════╝░░╚════╝░░░░╚═╝░░░╚══════╝
                                          
[18-Sep-24 15:02:22 - ERROR] - pyrogram.dispatcher - 'Bot' object has no attribute 'db_channel'
Traceback (most recent call last):
  File "/home/adithyan/.local/lib/python3.10/site-packages/pyrogram/dispatcher.py", line 317, in handler_worker
    await self.loop.run_in_executor(
  File "/usr/lib/python3.10/concurrent/futures/thread.py", line 58, in run
    result = self.fn(*self.args, **self.kwargs)
  File "/home/adithyan/.local/lib/python3.10/site-packages/pyrogram/sync.py", line 78, in async_to_sync_wrap
    return asyncio.run_coroutine_threadsafe(coroutine, main_loop).result()
  File "/usr/lib/python3.10/concurrent/futures/_base.py", line 458, in result
    return self.__get_result()
  File "/usr/lib/python3.10/concurrent/futures/_base.py", line 403, in __get_result
    raise self._exception
  File "/home/adithyan/.local/lib/python3.10/site-packages/pyromod/listen/message_handler.py", line 98, in resolve_future_or_callback
    await self.original_callback(client, message, *args)
  File "/home/adithyan/File-Sharing-Bot/plugins/link_generator.py", line 16, in batch
    f_msg_id = await get_message_id(client, first_message)
  File "/home/adithyan/File-Sharing-Bot/helper_func.py", line 67, in get_message_id
    if message.forward_from_chat.id == client.db_channel.id:
AttributeError: 'Bot' object has no attribute 'db_channel'
[18-Sep-24 15:12:37 - ERROR] - pyrogram.dispatcher - 'Bot' object has no attribute 'db_channel'
Traceback (most recent call last):
  File "/home/adithyan/.local/lib/python3.10/site-packages/pyrogram/dispatcher.py", line 317, in handler_worker
    await self.loop.run_in_executor(
  File "/usr/lib/python3.10/concurrent/futures/thread.py", line 58, in run
    result = self.fn(*self.args, **self.kwargs)
  File "/home/adithyan/.local/lib/python3.10/site-packages/pyrogram/sync.py", line 78, in async_to_sync_wrap
    return asyncio.run_coroutine_threadsafe(coroutine, main_loop).result()
  File "/usr/lib/python3.10/concurrent/futures/_base.py", line 458, in result
    return self.__get_result()
  File "/usr/lib/python3.10/concurrent/futures/_base.py", line 403, in __get_result
    raise self._exception
  File "/home/adithyan/.local/lib/python3.10/site-packages/pyromod/listen/message_handler.py", line 98, in resolve_future_or_callback
    await self.original_callback(client, message, *args)
  File "/home/adithyan/File-Sharing-Bot/plugins/channel_post.py", line 48, in new_post
    converted_id = message.id * abs(client.db_channel.id)
AttributeError: 'Bot' object has no attribute 'db_channel'
[18-Sep-24 15:14:29 - ERROR] - pyrogram.dispatcher - 'Bot' object has no attribute 'db_channel'
Traceback (most recent call last):
  File "/home/adithyan/.local/lib/python3.10/site-packages/pyrogram/dispatcher.py", line 317, in handler_worker
    await self.loop.run_in_executor(
  File "/usr/lib/python3.10/concurrent/futures/thread.py", line 58, in run
    result = self.fn(*self.args, **self.kwargs)
  File "/home/adithyan/.local/lib/python3.10/site-packages/pyrogram/sync.py", line 78, in async_to_sync_wrap
    return asyncio.run_coroutine_threadsafe(coroutine, main_loop).result()
  File "/usr/lib/python3.10/concurrent/futures/_base.py", line 458, in result
    return self.__get_result()
  File "/usr/lib/python3.10/concurrent/futures/_base.py", line 403, in __get_result
    raise self._exception
  File "/home/adithyan/.local/lib/python3.10/site-packages/pyromod/listen/message_handler.py", line 98, in resolve_future_or_callback
    await self.original_callback(client, message, *args)
  File "/home/adithyan/File-Sharing-Bot/plugins/link_generator.py", line 16, in batch
    f_msg_id = await get_message_id(client, first_message)
  File "/home/adithyan/File-Sharing-Bot/helper_func.py", line 67, in get_message_id
    if message.forward_from_chat.id == client.db_channel.id:
AttributeError: 'Bot' object has no attribute 'db_channel'
[18-Sep-24 15:15:41 - INFO] - root - Stop signal received (SIGINT). Exiting...
[18-Sep-24 15:15:41 - INFO] - bot - Bot stopped.
[18-Sep-24 15:17:32 - INFO] - bot - Bot Running..!

Created by 
https://t.me/CodeXBotz
[18-Sep-24 15:17:32 - INFO] - bot -  

       
░█████╗░░█████╗░██████╗░███████╗██╗░░██╗██████╗░░█████╗░████████╗███████╗
██╔══██╗██╔══██╗██╔══██╗██╔════╝╚██╗██╔╝██╔══██╗██╔══██╗╚══██╔══╝╚════██║
██║░░╚═╝██║░░██║██║░░██║█████╗░░░╚███╔╝░██████╦╝██║░░██║░░░██║░░░░░███╔═╝
██║░░██╗██║░░██║██║░░██║██╔══╝░░░██╔██╗░██╔══██╗██║░░██║░░░██║░░░██╔══╝░░
╚█████╔╝╚█████╔╝██████╔╝███████╗██╔╝╚██╗██████╦╝╚█████╔╝░░░██║░░░███████╗
░╚════╝░░╚════╝░╚═════╝░╚══════╝╚═╝░░╚═╝╚═════╝░░╚════╝░░░░╚═╝░░░╚══════╝
                                          
[18-Sep-24 15:18:37 - ERROR] - pyrogram.dispatcher - 'Bot' object has no attribute 'db_channel'
Traceback (most recent call last):
  File "/home/adithyan/.local/lib/python3.10/site-packages/pyrogram/dispatcher.py", line 315, in handler_worker
    await handler.callback(self.client, *args)
  File "/home/adithyan/.local/lib/python3.10/site-packages/pyromod/listen/listen.py", line 93, in resolve_listener
    await self.user_callback(client, message, *args)
  File "/home/adithyan/File-Sharing-Bot/plugins/channel_post.py", line 48, in new_post
    converted_id = message.id * abs(client.db_channel.id)
AttributeError: 'Bot' object has no attribute 'db_channel'
[18-Sep-24 15:18:38 - ERROR] - pyrogram.dispatcher - 'Bot' object has no attribute 'db_channel'
Traceback (most recent call last):
  File "/home/adithyan/.local/lib/python3.10/site-packages/pyrogram/dispatcher.py", line 315, in handler_worker
    await handler.callback(self.client, *args)
  File "/home/adithyan/.local/lib/python3.10/site-packages/pyromod/listen/listen.py", line 93, in resolve_listener
    await self.user_callback(client, message, *args)
  File "/home/adithyan/File-Sharing-Bot/plugins/channel_post.py", line 48, in new_post
    converted_id = message.id * abs(client.db_channel.id)
AttributeError: 'Bot' object has no attribute 'db_channel'
[18-Sep-24 15:18:38 - ERROR] - pyrogram.dispatcher - 'Bot' object has no attribute 'db_channel'
Traceback (most recent call last):
  File "/home/adithyan/.local/lib/python3.10/site-packages/pyrogram/dispatcher.py", line 315, in handler_worker
    await handler.callback(self.client, *args)
  File "/home/adithyan/.local/lib/python3.10/site-packages/pyromod/listen/listen.py", line 93, in resolve_listener
    await self.user_callback(client, message, *args)
  File "/home/adithyan/File-Sharing-Bot/plugins/channel_post.py", line 48, in new_post
    converted_id = message.id * abs(client.db_channel.id)
AttributeError: 'Bot' object has no attribute 'db_channel'
[18-Sep-24 15:18:39 - ERROR] - pyrogram.dispatcher - 'Bot' object has no attribute 'db_channel'
Traceback (most recent call last):
  File "/home/adithyan/.local/lib/python3.10/site-packages/pyrogram/dispatcher.py", line 315, in handler_worker
    await handler.callback(self.client, *args)
  File "/home/adithyan/.local/lib/python3.10/site-packages/pyromod/listen/listen.py", line 93, in resolve_listener
    await self.user_callback(client, message, *args)
  File "/home/adithyan/File-Sharing-Bot/plugins/channel_post.py", line 48, in new_post
    converted_id = message.id * abs(client.db_channel.id)
AttributeError: 'Bot' object has no attribute 'db_channel'
[18-Sep-24 15:18:40 - ERROR] - pyrogram.dispatcher - 'Bot' object has no attribute 'db_channel'
Traceback (most recent call last):
  File "/home/adithyan/.local/lib/python3.10/site-packages/pyrogram/dispatcher.py", line 315, in handler_worker
    await handler.callback(self.client, *args)
  File "/home/adithyan/.local/lib/python3.10/site-packages/pyromod/listen/listen.py", line 93, in resolve_listener
    await self.user_callback(client, message, *args)
  File "/home/adithyan/File-Sharing-Bot/plugins/channel_post.py", line 48, in new_post
    converted_id = message.id * abs(client.db_channel.id)
AttributeError: 'Bot' object has no attribute 'db_channel'
[18-Sep-24 15:18:40 - ERROR] - pyrogram.dispatcher - 'Bot' object has no attribute 'db_channel'
Traceback (most recent call last):
  File "/home/adithyan/.local/lib/python3.10/site-packages/pyrogram/dispatcher.py", line 315, in handler_worker
    await handler.callback(self.client, *args)
  File "/home/adithyan/.local/lib/python3.10/site-packages/pyromod/listen/listen.py", line 93, in resolve_listener
    await self.user_callback(client, message, *args)
  File "/home/adithyan/File-Sharing-Bot/plugins/channel_post.py", line 48, in new_post
    converted_id = message.id * abs(client.db_channel.id)
AttributeError: 'Bot' object has no attribute 'db_channel'
[18-Sep-24 15:18:41 - ERROR] - pyrogram.dispatcher - 'Bot' object has no attribute 'db_channel'
Traceback (most recent call last):
  File "/home/adithyan/.local/lib/python3.10/site-packages/pyrogram/dispatcher.py", line 315, in handler_worker
    await handler.callback(self.client, *args)
  File "/home/adithyan/.local/lib/python3.10/site-packages/pyromod/listen/listen.py", line 93, in resolve_listener
    await self.user_callback(client, message, *args)
  File "/home/adithyan/File-Sharing-Bot/plugins/channel_post.py", line 48, in new_post
    converted_id = message.id * abs(client.db_channel.id)
AttributeError: 'Bot' object has no attribute 'db_channel'
[18-Sep-24 15:18:46 - ERROR] - pyrogram.dispatcher - 'Bot' object has no attribute 'db_channel'
Traceback (most recent call last):
  File "/home/adithyan/.local/lib/python3.10/site-packages/pyrogram/dispatcher.py", line 315, in handler_worker
    await handler.callback(self.client, *args)
  File "/home/adithyan/.local/lib/python3.10/site-packages/pyromod/listen/listen.py", line 93, in resolve_listener
    await self.user_callback(client, message, *args)
  File "/home/adithyan/File-Sharing-Bot/plugins/channel_post.py", line 48, in new_post
    converted_id = message.id * abs(client.db_channel.id)
AttributeError: 'Bot' object has no attribute 'db_channel'
[18-Sep-24 15:18:47 - ERROR] - pyrogram.dispatcher - 'Bot' object has no attribute 'db_channel'
Traceback (most recent call last):
  File "/home/adithyan/.local/lib/python3.10/site-packages/pyrogram/dispatcher.py", line 315, in handler_worker
    await handler.callback(self.client, *args)
  File "/home/adithyan/.local/lib/python3.10/site-packages/pyromod/listen/listen.py", line 93, in resolve_listener
    await self.user_callback(client, message, *args)
  File "/home/adithyan/File-Sharing-Bot/plugins/channel_post.py", line 48, in new_post
    converted_id = message.id * abs(client.db_channel.id)
AttributeError: 'Bot' object has no attribute 'db_channel'
[18-Sep-24 15:18:47 - ERROR] - pyrogram.dispatcher - 'Bot' object has no attribute 'db_channel'
Traceback (most recent call last):
  File "/home/adithyan/.local/lib/python3.10/site-packages/pyrogram/dispatcher.py", line 315, in handler_worker
    await handler.callback(self.client, *args)
  File "/home/adithyan/.local/lib/python3.10/site-packages/pyromod/listen/listen.py", line 93, in resolve_listener
    await self.user_callback(client, message, *args)
  File "/home/adithyan/File-Sharing-Bot/plugins/channel_post.py", line 48, in new_post
    converted_id = message.id * abs(client.db_channel.id)
AttributeError: 'Bot' object has no attribute 'db_channel'
[18-Sep-24 15:18:48 - ERROR] - pyrogram.dispatcher - 'Bot' object has no attribute 'db_channel'
Traceback (most recent call last):
  File "/home/adithyan/.local/lib/python3.10/site-packages/pyrogram/dispatcher.py", line 315, in handler_worker
    await handler.callback(self.client, *args)
  File "/home/adithyan/.local/lib/python3.10/site-packages/pyromod/listen/listen.py", line 93, in resolve_listener
    await self.user_callback(client, message, *args)
  File "/home/adithyan/File-Sharing-Bot/plugins/channel_post.py", line 48, in new_post
    converted_id = message.id * abs(client.db_channel.id)
AttributeError: 'Bot' object has no attribute 'db_channel'
[18-Sep-24 15:18:49 - ERROR] - pyrogram.dispatcher - 'Bot' object has no attribute 'db_channel'
Traceback (most recent call last):
  File "/home/adithyan/.local/lib/python3.10/site-packages/pyrogram/dispatcher.py", line 315, in handler_worker
    await handler.callback(self.client, *args)
  File "/home/adithyan/.local/lib/python3.10/site-packages/pyromod/listen/listen.py", line 93, in resolve_listener
    await self.user_callback(client, message, *args)
  File "/home/adithyan/File-Sharing-Bot/plugins/channel_post.py", line 48, in new_post
    converted_id = message.id * abs(client.db_channel.id)
AttributeError: 'Bot' object has no attribute 'db_channel'
[18-Sep-24 15:18:49 - ERROR] - pyrogram.dispatcher - 'Bot' object has no attribute 'db_channel'
Traceback (most recent call last):
  File "/home/adithyan/.local/lib/python3.10/site-packages/pyrogram/dispatcher.py", line 315, in handler_worker
    await handler.callback(self.client, *args)
  File "/home/adithyan/.local/lib/python3.10/site-packages/pyromod/listen/listen.py", line 93, in resolve_listener
    await self.user_callback(client, message, *args)
  File "/home/adithyan/File-Sharing-Bot/plugins/channel_post.py", line 48, in new_post
    converted_id = message.id * abs(client.db_channel.id)
AttributeError: 'Bot' object has no attribute 'db_channel'
[18-Sep-24 15:18:50 - ERROR] - pyrogram.dispatcher - 'Bot' object has no attribute 'db_channel'
Traceback (most recent call last):
  File "/home/adithyan/.local/lib/python3.10/site-packages/pyrogram/dispatcher.py", line 315, in handler_worker
    await handler.callback(self.client, *args)
  File "/home/adithyan/.local/lib/python3.10/site-packages/pyromod/listen/listen.py", line 93, in resolve_listener
    await self.user_callback(client, message, *args)
  File "/home/adithyan/File-Sharing-Bot/plugins/channel_post.py", line 48, in new_post
    converted_id = message.id * abs(client.db_channel.id)
AttributeError: 'Bot' object has no attribute 'db_channel'
[18-Sep-24 15:18:50 - ERROR] - pyrogram.dispatcher - 'Bot' object has no attribute 'db_channel'
Traceback (most recent call last):
  File "/home/adithyan/.local/lib/python3.10/site-packages/pyrogram/dispatcher.py", line 315, in handler_worker
    await handler.callback(self.client, *args)
  File "/home/adithyan/.local/lib/python3.10/site-packages/pyromod/listen/listen.py", line 93, in resolve_listener
    await self.user_callback(client, message, *args)
  File "/home/adithyan/File-Sharing-Bot/plugins/channel_post.py", line 48, in new_post
    converted_id = message.id * abs(client.db_channel.id)
AttributeError: 'Bot' object has no attribute 'db_channel'
[18-Sep-24 15:19:23 - INFO] - root - Stop signal received (SIGINT). Exiting...
[18-Sep-24 15:19:23 - INFO] - root - Stop signal received (SIGINT). Exiting...
[18-Sep-24 15:19:23 - INFO] - root - Stop signal received (SIGINT). Exiting...
[18-Sep-24 15:19:25 - INFO] - bot - Bot stopped.
[18-Sep-24 15:19:35 - INFO] - bot - Bot Running..!

Created by 
https://t.me/CodeXBotz
[18-Sep-24 15:19:35 - INFO] - bot -  

       
░█████╗░░█████╗░██████╗░███████╗██╗░░██╗██████╗░░█████╗░████████╗███████╗
██╔══██╗██╔══██╗██╔══██╗██╔════╝╚██╗██╔╝██╔══██╗██╔══██╗╚══██╔══╝╚════██║
██║░░╚═╝██║░░██║██║░░██║█████╗░░░╚███╔╝░██████╦╝██║░░██║░░░██║░░░░░███╔═╝
██║░░██╗██║░░██║██║░░██║██╔══╝░░░██╔██╗░██╔══██╗██║░░██║░░░██║░░░██╔══╝░░
╚█████╔╝╚█████╔╝██████╔╝███████╗██╔╝╚██╗██████╦╝╚█████╔╝░░░██║░░░███████╗
░╚════╝░░╚════╝░╚═════╝░╚══════╝╚═╝░░╚═╝╚═════╝░░╚════╝░░░░╚═╝░░░╚══════╝
                                          
[18-Sep-24 15:19:44 - INFO] - root - Stop signal received (SIGINT). Exiting...
[18-Sep-24 15:19:48 - INFO] - bot - Bot stopped.
[18-Sep-24 15:24:42 - INFO] - bot - Bot Running..!

Created by 
https://t.me/CodeXBotz
[18-Sep-24 15:24:42 - INFO] - bot -  

       
░█████╗░░█████╗░██████╗░███████╗██╗░░██╗██████╗░░█████╗░████████╗███████╗
██╔══██╗██╔══██╗██╔══██╗██╔════╝╚██╗██╔╝██╔══██╗██╔══██╗╚══██╔══╝╚════██║
██║░░╚═╝██║░░██║██║░░██║█████╗░░░╚███╔╝░██████╦╝██║░░██║░░░██║░░░░░███╔═╝
██║░░██╗██║░░██║██║░░██║██╔══╝░░░██╔██╗░██╔══██╗██║░░██║░░░██║░░░██╔══╝░░
╚█████╔╝╚█████╔╝██████╔╝███████╗██╔╝╚██╗██████╦╝╚█████╔╝░░░██║░░░███████╗
░╚════╝░░╚════╝░╚═════╝░╚══════╝╚═╝░░╚═╝╚═════╝░░╚════╝░░░░╚═╝░░░╚══════╝
                                          
[18-Sep-24 15:24:54 - ERROR] - pyrogram.dispatcher - 'Bot' object has no attribute 'db_channel'
Traceback (most recent call last):
  File "/home/adithyan/.local/lib/python3.10/site-packages/pyrogram/dispatcher.py", line 240, in handler_worker
    await handler.callback(self.client, *args)
  File "/home/adithyan/.local/lib/python3.10/site-packages/pyromod/listen/listen.py", line 93, in resolve_listener
    await self.user_callback(client, message, *args)
  File "/home/adithyan/File-Sharing-Bot/plugins/link_generator.py", line 16, in batch
    f_msg_id = await get_message_id(client, first_message)
  File "/home/adithyan/File-Sharing-Bot/helper_func.py", line 67, in get_message_id
    if message.forward_from_chat.id == client.db_channel.id:
AttributeError: 'Bot' object has no attribute 'db_channel'
[18-Sep-24 15:26:12 - INFO] - root - Stop signal received (SIGINT). Exiting...
[18-Sep-24 15:26:14 - INFO] - bot - Bot stopped.
[18-Sep-24 15:28:30 - INFO] - bot - Bot Running..!

Created by 
https://t.me/CodeXBotz
[18-Sep-24 15:28:30 - INFO] - bot -  

       
░█████╗░░█████╗░██████╗░███████╗██╗░░██╗██████╗░░█████╗░████████╗███████╗
██╔══██╗██╔══██╗██╔══██╗██╔════╝╚██╗██╔╝██╔══██╗██╔══██╗╚══██╔══╝╚════██║
██║░░╚═╝██║░░██║██║░░██║█████╗░░░╚███╔╝░██████╦╝██║░░██║░░░██║░░░░░███╔═╝
██║░░██╗██║░░██║██║░░██║██╔══╝░░░██╔██╗░██╔══██╗██║░░██║░░░██║░░░██╔══╝░░
╚█████╔╝╚█████╔╝██████╔╝███████╗██╔╝╚██╗██████╦╝╚█████╔╝░░░██║░░░███████╗
░╚════╝░░╚════╝░╚═════╝░╚══════╝╚═╝░░╚═╝╚═════╝░░╚════╝░░░░╚═╝░░░╚══════╝
                                          
[18-Sep-24 15:28:49 - ERROR] - pyrogram.dispatcher - 'Bot' object has no attribute 'db_channel'
Traceback (most recent call last):
  File "/home/adithyan/.local/lib/python3.10/site-packages/pyrogram/dispatcher.py", line 242, in handler_worker
    await self.loop.run_in_executor(
  File "/usr/lib/python3.10/concurrent/futures/thread.py", line 58, in run
    result = self.fn(*self.args, **self.kwargs)
  File "/home/adithyan/.local/lib/python3.10/site-packages/pyrogram/sync.py", line 78, in async_to_sync_wrap
    return asyncio.run_coroutine_threadsafe(coroutine, main_loop).result()
  File "/usr/lib/python3.10/concurrent/futures/_base.py", line 458, in result
    return self.__get_result()
  File "/usr/lib/python3.10/concurrent/futures/_base.py", line 403, in __get_result
    raise self._exception
  File "/home/adithyan/.local/lib/python3.10/site-packages/pyromod/listen/message_handler.py", line 98, in resolve_future_or_callback
    await self.original_callback(client, message, *args)
  File "/home/adithyan/File-Sharing-Bot/plugins/link_generator.py", line 16, in batch
    f_msg_id = await get_message_id(client, first_message)
  File "/home/adithyan/File-Sharing-Bot/helper_func.py", line 67, in get_message_id
    if message.forward_from_chat.id == client.db_channel.id:
AttributeError: 'Bot' object has no attribute 'db_channel'
[18-Sep-24 15:31:54 - INFO] - root - Stop signal received (SIGINT). Exiting...
[18-Sep-24 15:31:54 - INFO] - bot - Bot stopped.
[18-Sep-24 15:32:03 - INFO] - bot - Bot Running..!

Created by 
https://t.me/CodeXBotz
[18-Sep-24 15:32:03 - INFO] - bot -  

       
░█████╗░░█████╗░██████╗░███████╗██╗░░██╗██████╗░░█████╗░████████╗███████╗
██╔══██╗██╔══██╗██╔══██╗██╔════╝╚██╗██╔╝██╔══██╗██╔══██╗╚══██╔══╝╚════██║
██║░░╚═╝██║░░██║██║░░██║█████╗░░░╚███╔╝░██████╦╝██║░░██║░░░██║░░░░░███╔═╝
██║░░██╗██║░░██║██║░░██║██╔══╝░░░██╔██╗░██╔══██╗██║░░██║░░░██║░░░██╔══╝░░
╚█████╔╝╚█████╔╝██████╔╝███████╗██╔╝╚██╗██████╦╝╚█████╔╝░░░██║░░░███████╗
░╚════╝░░╚════╝░╚═════╝░╚══════╝╚═╝░░╚═╝╚═════╝░░╚════╝░░░░╚═╝░░░╚══════╝
                                          
[18-Sep-24 16:06:42 - INFO] - root - Stop signal received (SIGINT). Exiting...
[18-Sep-24 16:06:46 - INFO] - bot - Bot stopped.
[18-Sep-24 16:07:00 - INFO] - bot - Bot Running..!

Created by 
https://t.me/CodeXBotz
[18-Sep-24 16:07:00 - INFO] - bot -  

       
░█████╗░░█████╗░██████╗░███████╗██╗░░██╗██████╗░░█████╗░████████╗███████╗
██╔══██╗██╔══██╗██╔══██╗██╔════╝╚██╗██╔╝██╔══██╗██╔══██╗╚══██╔══╝╚════██║
██║░░╚═╝██║░░██║██║░░██║█████╗░░░╚███╔╝░██████╦╝██║░░██║░░░██║░░░░░███╔═╝
██║░░██╗██║░░██║██║░░██║██╔══╝░░░██╔██╗░██╔══██╗██║░░██║░░░██║░░░██╔══╝░░
╚█████╔╝╚█████╔╝██████╔╝███████╗██╔╝╚██╗██████╦╝╚█████╔╝░░░██║░░░███████╗
░╚════╝░░╚════╝░╚═════╝░╚══════╝╚═╝░░╚═╝╚═════╝░░╚════╝░░░░╚═╝░░░╚══════╝
                                          
[18-Sep-24 16:11:53 - INFO] - root - Stop signal received (SIGINT). Exiting...
[18-Sep-24 16:11:54 - INFO] - bot - Bot stopped.
